<?xml version="1.0"?>

<robot name="scara">
    
    <!-- Linkages  -->
    <link name="lk0">
    	<visual>
    	    <origin xyz="0.0 0.0 0.0" rpy="0.0 0.0 0.0"/>
    	    <geometry>
		<mesh filename="package://scara/meshes/visual/lk0.dae" scale="1.0 1.0 1.0" />
    	    </geometry>
    	    <material name="black">
    	    	<color rgba="0.4 0.4 0.4 1.0"/>
    	    </material>
    	</visual>
    	<collision>
    	    <origin xyz="0.0 0.0 0.0" rpy="0.0 0.0 0.0"/>
    	    <geometry>
		<mesh filename="package://scara/meshes/collision/lk0.stl" scale="0.001 0.001 0.001" />
    	    </geometry>
    	</collision>
    	<inertial>
            <origin xyz="0 0 0" rpy="0 0 0"/>
            <mass value="1"/>
            <inertia ixx="1"  ixy="0"  ixz="0" iyy="1" iyz="0" izz="1" />
       </inertial>
    </link>

    <link name="lk1">
    	<visual>
    	    <origin xyz="0.0 0.0 0.0" rpy="0.0 0.0 0.0"/>
    	    <geometry>
		<mesh filename="package://scara/meshes/visual/lk1.dae" scale="1.0 1.0 1.0" />
    	    </geometry>
    	    <material name="yellow">
    	    	<color rgba="1.0 1.0 0.0 1.0"/>
    	    </material>
    	</visual>
    	<collision>
    	    <origin xyz="0.0 0.0 0.0" rpy="0.0 0.0 0.0"/>
    	    <geometry>
	         <mesh filename="package://scara/meshes/collision/lk1.stl" scale="0.001 0.001 0.001" />
    	    </geometry>
    	</collision> 
    	<inertial>
            <origin xyz="0 0 0" rpy="0 0 0"/>
            <mass value="1"/>
            <inertia ixx="1"  ixy="0"  ixz="0" iyy="1" iyz="0" izz="1" />
       </inertial>
    </link>

    <link name="lk2">
    	<visual>
    	    <origin xyz="0.0 0.0 0.0" rpy="0.0 0.0 0.0"/>
    	    <geometry>
	        <mesh filename="package://scara/meshes/visual/lk2.dae" scale="1.0 1.0 1.0" />
    	    </geometry>
    	    <material name="yellow">
    	    	<color rgba="1.0 1.0 0.0 1.0"/>
    	    </material>
    	</visual>
    	<collision>
    	    <origin xyz="0.0 0.0 0.0" rpy="0.0 0.0 0.0"/>
    	    <geometry>
	        <mesh filename="package://scara/meshes/collision/lk2.stl" scale="0.001 0.001 0.001" />
    	    </geometry>
    	</collision> 
    	<inertial>
            <origin xyz="0 0 0" rpy="0 0 0"/>
            <mass value="1"/>
            <inertia ixx="1"  ixy="0"  ixz="0" iyy="1" iyz="0" izz="1" />
       </inertial>
    </link>

    <link name="dummy">
        <inertial>
            <origin xyz="0 0 0" rpy="0 0 0"/>
            <mass value="1"/>
            <inertia ixx="1"  ixy="0"  ixz="0" iyy="1" iyz="0" izz="1" />
        </inertial>
    </link>

    <link name="lk3">
    	<visual>
    	    <origin xyz="0.0 0.0 0.0" rpy="0.0 0.0 0.0"/>
    	    <geometry>
	        <mesh filename="package://scara/meshes/visual/lk3.dae" scale="1.0 1.0 1.0" />
    	    </geometry>
    	    <material name="silver">
    	    	<color rgba="0.8 0.8 0.8 1.0"/>
    	    </material>
    	</visual>
    	<collision>
    	    <origin xyz="0.0 0.0 0.0" rpy="0.0 0.0 0.0"/>
    	    <geometry>
	        <mesh filename="package://scara/meshes/collision/lk3.stl" scale="0.001 0.001 0.001" />
    	    </geometry>
    	</collision> 
    	<inertial>
            <origin xyz="0 0 0" rpy="0 0 0"/>
            <mass value="1"/>
            <inertia ixx="1"  ixy="0"  ixz="0" iyy="1" iyz="0" izz="1" />
       </inertial>
    </link>

    
    <!-- Joints -->
    <joint name="q1" type="revolute">
    	<parent link="lk0"/>
    	<child link="lk1"/>
    	<axis xyz="0.0 0.0 1.0"/>
    	<limit lower="-3.1416" upper="3.1416" effort="1.0" velocity="1.0"/>
    	<origin xyz="0.0 0.0 0.18" rpy="0.0 0.0 0.0" />
    </joint>

    <joint name="q2" type="revolute">
    	<parent link="lk1"/>
    	<child link="lk2"/>
    	<axis xyz="0.0 0.0 1.0"/>
    	<limit lower="-3.1416" upper="3.1416" effort="1.0" velocity="1.0"/>
    	<origin xyz="0.3 0.0 0.04" rpy="0.0 0.0 0.0" />
    </joint>

    <joint name="q3" type="prismatic">
    	<parent link="lk2"/>
    	<child link="dummy"/>
    	<axis xyz="0.0 0.0 1.0"/>
    	<limit lower="0.0" upper="0.225" effort="1.0" velocity="1.0"/>
    	<origin xyz="0.25 0.0 -0.02" rpy="3.1416 0.0 0.0" />
    </joint>

    <joint name="q4" type="revolute">
    	<parent link="dummy"/>
    	<child link="lk3"/>
    	<axis xyz="0.0 0.0 1.0"/>
    	<limit lower="-3.1416" upper="3.1416" effort="1.0" velocity="1.0"/>
    	<origin xyz="0.0 0.0 0.0" rpy="0.0 0.0 0.0" />
    </joint>

</robot>
